Workbook

Sheet Instructions
A1: SECURITY SELF-ASSESSMENT: GZAC
A3: Benchmark: EXT-BM-GZAC v1.0
A4: Versie: 11.x+
A5: Bron: docs.gzac.nl + Camunda Security
A7: GZAC (Valtimo) is een BPM platform voor Zaakgericht Werken, gebaseerd op Camunda en KeyCloak.
A9: INSTRUCTIES
A11: 1. Ga naar het tabblad 'Assessment'
A12: 2. Review elke maatregel en de beschrijving
A13: 3. Controleer de BASELINE kolom - deze is vooraf ingevuld maar aanpasbaar
A14: 4. Voer de Audit Procedure uit om de huidige status te bepalen
A15: 5. Vul de STATUS in via de dropdown:
A16: • Compliant: Volledig geïmplementeerd en geverifieerd
... A56: Goedkeuringsdatum:

Sheet Assessment
A1: ID | B1: Level | C1: Baseline | D1: CIS Controls | E1: Control Title | F1: Control Description | G1: Audit Procedure | H1: Expected Config | I1: Status | J1: Evidence Location | K1: Comments | L1: Responsible Party
A2: 1. Authentication (KeyCloak)
A3: GZ-1.1 | B3: L1 | C3: Ja | D3: CIS-5.6, CIS-6.1 | E3: KeyCloak integratie actief | F3: GZAC is geconfigureerd met KeyCloak als identity provider via OIDC. | G3: grep -A 10 "keycloak:" application.yml curl https://gzac/.well-known/openid-configuration | H3: OIDC config aanwezig
A4: GZ-1.2 | B4: L1 | C4: Ja | D4: CIS-6.1 | E4: JWT token validatie | F4: JWT tokens worden correct gevalideerd op signature, expiry en issuer. | G4: Test with invalid token (should fail) | H4: 401 response
A5: GZ-1.3 | B5: L1 | C5: Ja | D5: CIS-6.2 | E5: Token expiry geconfigureerd | F5: Access tokens hebben een korte levensduur (aanbevolen: 5-15 minuten). | G5: KeyCloak admin: Realm Settings → Tokens → Access Token Lifespan | H5: 5-15 minuten
A6: GZ-1.4 | B6: L2 | C6: Nee | D6: CIS-6.2 | E6: Refresh token rotation | F6: Refresh token rotation is ingeschakeld voor extra beveiliging. | G6: KeyCloak admin: Realm Settings → Tokens → Refresh Token | H6: Rotation enabled
A7: 2. Authorization
A8: GZ-2.1 | B8: L1 | C8: Ja | D8: CIS-6.8 | E8: Role-based access control | F8: RBAC is geconfigureerd met specifieke rollen voor verschillende functies. | G8: KeyCloak: check Realm Roles en Client Roles | H8: Rollen gedefinieerd
A9: GZ-2.2 | B9: L1 | C9: Ja | D9: CIS-6.6, CIS-6.8 | E9: Case-level permissions | F9: Toegang tot zaken is beperkt op basis van zaaktype en rol. | G9: Test access with different roles | H9: Role-based filtering
A10: GZ-2.3 | B10: L1 | C10: Ja | D10: CIS-6.6 | E10: Task assignment security | F10: Taken kunnen alleen worden geclaimd en afgerond door geautoriseerde gebruikers. | G10: Test task claim/complete with unauthorized user | H10: 403 bij unauthorized
A11: 3. Process Security (Camunda)
A12: GZ-3.1 | B12: L1 | C12: Ja | D12: CIS-5.4, CIS-16.1 | E12: Process deployment beperkt | F12: Alleen beheerders kunnen processdefinities deployen. | G12: Check deployment permissions in configuration | H12: Deployment restricted
A13: GZ-3.2 | B13: L1 | C13: Ja | D13: CIS-16.10, CIS-4.1 | E13: Script task security | F13: Script tasks (Groovy/JavaScript) zijn beperkt of uitgeschakeld, of draaien in sandbox. | G13: Review process definitions for script tasks | H13: Scripts in sandbox of beperkt
A14: GZ-3.3 | B14: L1 | C14: Ja | D14: CIS-6.1 | E14: External task handler auth | F14: External task handlers authenticeren zich bij het claimen van taken. | G14: Check external task worker configuration | H14: Worker auth required
A15: 4. API Security
A16: GZ-4.1 | B16: L1 | C16: Ja | D16: CIS-6.1, CIS-6.3 | E16: API authenticatie verplicht | F16: Alle API endpoints vereisen authenticatie. | G16: curl -I https://gzac/api/v1/case (should return 401) | H16: 401 response
A17: GZ-4.2 | B17: L1 | C17: Ja | D17: CIS-3.10 | E17: HTTPS verplicht | F17: Alleen HTTPS is toegestaan, HTTP wordt geredirect of geblokkeerd. | G17: curl -I http://gzac (should redirect or fail) | H17: Redirect of block
A18: GZ-4.3 | B18: L1 | C18: Ja | D18: CIS-4.2, CIS-16.10 | E18: CORS restrictief | F18: CORS is restrictief geconfigureerd voor alleen toegestane origins. | G18: grep "cors" application.yml | H18: Specifieke origins
A19: 5. Integration Security
A20: GZ-5.1 | B20: L1 | C20: Ja | D20: CIS-3.10, CIS-6.1 | E20: OpenZaak integratie beveiligd | F20: Communicatie met OpenZaak gebruikt JWT tokens en HTTPS. | G20: Check OpenZaak connector configuration | H20: JWT + HTTPS
A21: GZ-5.2 | B21: L1 | C21: Ja | D21: CIS-3.11, CIS-4.1 | E21: Secrets management | F21: API keys en credentials worden opgeslagen in secrets (K8s secrets, vault), niet in config files. | G21: grep -r "password\|secret\|apiKey" application*.yml | H21: Geen hardcoded secrets
A22: GZ-5.3 | B22: L2 | C22: Nee | D22: CIS-16.4, CIS-16.12 | E22: Plugin security review | F22: Custom plugins zijn gereviewd op security risicos voordat ze worden gedeployed. | G22: Review plugin deployment process | H22: Review process aanwezig
A23: 6. Logging & Audit
A24: GZ-6.1 | B24: L1 | C24: Ja | D24: CIS-8.2, CIS-8.1 | E24: Audit logging enabled | F24: Audit logging is ingeschakeld voor alle zaak- en taakacties. | G24: Check logging configuration | H24: Audit logging on
A25: GZ-6.2 | B25: L1 | C25: Ja | D25: CIS-8.10 | E25: Process history retention | F25: Process history wordt bewaard voor audit doeleinden (conform archiefwet). | G25: Check Camunda history configuration | H25: History retention configured
A26: GZ-6.3 | B26: L1 | C26: Ja | D26: CIS-8.2, CIS-8.5 | E26: Security event logging | F26: Security events (login failures, permission denied) worden gelogd. | G26: Review security log samples | H26: Security events logged

Sheet Summary Dashboard
A1: Metric | B1: Value
A2: Assessment: GZAC
A4: OVERZICHT
A5: Totaal L1 Maatregelen | B5: 17
A6: Totaal L2 Maatregelen | B6: 2
A7: Totaal Maatregelen | B7: 19
A9: BASELINE ANALYSE
A10: Baseline maatregelen (berekend) | B10: 17
A11: Baseline maatregelen (huidig) | B11: =COUNTIF(Assessment!C:C,"Ja") -> 17
A12: Niet-baseline maatregelen | B12: =COUNTIF(Assessment!C:C,"Nee") -> 2
A14: STATUS TELLING (alle maatregelen)
A15: Compliant | B15: =COUNTIF(Assessment!I:I,"Compliant") -> 0
A16: Partial | B16: =COUNTIF(Assessment!I:I,"Partial") -> 0
A17: Non-Compliant | B17: =COUNTIF(Assessment!I:I,"Non-Compliant") -> 0
A18: N/A | B18: =COUNTIF(Assessment!I:I,"N/A") -> 0
A20: BASELINE STATUS (alleen baseline=Ja)
A21: Baseline Compliant | B21: =COUNTIFS(Assessment!C:C,"Ja",Assessment!I:I,"Compliant") -> 0
A22: Baseline Partial | B22: =COUNTIFS(Assessment!C:C,"Ja",Assessment!I:I,"Partial") -> 0
A23: Baseline Non-Compliant | B23: =COUNTIFS(Assessment!C:C,"Ja",Assessment!I:I,"Non-Compliant") -> 0
A24: Baseline N/A | B24: =COUNTIFS(Assessment!C:C,"Ja",Assessment!I:I,"N/A") -> 0
A26: COMPLIANCE SCORES
A27: Totaal Score % (excl. N/A) | B27: =IF((B14+B15+B16)>0,ROUND(B14/(B14+B15+B16)*100,1),0) -> 0
A28: Baseline Score % (excl. N/A) | B28: =IF((B20+B21+B22)>0,ROUND(B20/(B20+B21+B22)*100,1),0) -> 0
A30: SCORE INTERPRETATIE
A31: 90-100%: Uitstekend | B31: Onderhoud huidige status
A32: 75-89%: Goed | B32: Plan verbeteringen
A33: 50-74%: Matig | B33: Actie vereist binnen 3 maanden
A34: 0-49%: Onvoldoende | B34: Urgente actie vereist

Sheet Export
A1: EXPORTEER ASSESSMENT RESULTATEN NAAR VAULT
A3: Vul onderstaande gegevens in:
A5: Assessor:
A6: Systeem: | B6: XENA-ZGW
A7: Omgeving: | B7: Productie
A8: Assessment Datum: | B8: 2026-02-11
A9: Goedgekeurd door:
A11: EXPORT KNOP
A12: [ Exporteer naar Vault ]
A14: MACRO INSTALLATIE (eenmalig)
A15: 1. Open dit bestand in Excel
A16: 2. Druk Alt+F11 om de VBA Editor te openen
A17: 3. Ga naar File > Import File
A18: 4. Selecteer: SCF_Export_Module.bas (zelfde map als dit bestand)
A19: 5. Sluit de VBA Editor (Alt+Q)
A20: 6. In Excel: druk Alt+F8, selecteer 'CreateExportButton', klik Run
A21: 7. Sla het bestand op als .xlsm (Excel Macro-Enabled Workbook)
A23: Na installatie: klik op de knop hierboven om te exporteren.
... A32: benchmark: EXT-BM-GZAC-v1.0
A33: =CONCATENATE("assessment_date: """,B8,"""") -> assessment_date: "2026-02-11"
A34: =CONCATENATE("export_timestamp: """,TEXT(NOW(),"YYYY-MM-DD HH:MM:SS"),"""") -> export_timestamp: "2026-02-11 10:46:44"
A35: =CONCATENATE("assessor: """,B5,"""") -> assessor: ""
A36: =CONCATENATE("system: """,B6,"""") -> system: "XENA-ZGW"
A37: =CONCATENATE("environment: """,B7,"""") -> environment: "Productie"
A38: =CONCATENATE("approved_by: """,B9,"""") -> approved_by: ""
A40: # Scores
A41: =CONCATENATE("total_score: ",'Summary Dashboard'!B27) -> total_score: 0
A42: =CONCATENATE("baseline_score: ",'Summary Dashboard'!B28) -> baseline_score: 0
A44: # Tellingen
A45: =CONCATENATE("total_measures: ",'Summary Dashboard'!B6) -> total_measures: 2
A46: =CONCATENATE("baseline_measures: ",'Summary Dashboard'!B10) -> baseline_measures: 17
A48: =CONCATENATE("compliant: ",'Summary Dashboard'!B14) -> compliant:
A49: =CONCATENATE("partial: ",'Summary Dashboard'!B15) -> partial: 0
A50: =CONCATENATE("non_compliant: ",'Summary Dashboard'!B16) -> non_compliant: 0
A51: =CONCATENATE("na: ",'Summary Dashboard'!B17) -> na: 0
A53: =CONCATENATE("baseline_compliant: ",'Summary Dashboard'!B20) -> baseline_compliant:
A54: =CONCATENATE("baseline_partial: ",'Summary Dashboard'!B21) -> baseline_partial: 0
A55: =CONCATENATE("baseline_non_compliant: ",'Summary Dashboard'!B22) -> baseline_non_compliant: 0
A56: =CONCATENATE("baseline_na: ",'Summary Dashboard'!B23) -> baseline_na: 0
A57: ---
...
